<robot name="marsha">
    <link name="Link_0"/>
    <link name="Link_1"/>
    <link name="Link_2"/>
    <link name="Link_3"/>
    <link name="Link_4"/>
    <link name="Link_5"/>
    <link name="Link_6"/>
    <link name="Link_7"/>

    <joint name="Joint_0" type="continuous">
        <parent link="Link_0"/>
        <child link="Link_1"/>
        <origin xyz="0 0 0" rpy="0 0 0" />
    </joint>

    <joint name="Joint_1" type="continuous">
        <parent link="Link_1"/>
        <child link="Link_2"/>
        <origin xyz="0 0 0" rpy="0 0 0" />
    </joint>

    <joint name="Joint_2" type="continuous">
        <parent link="Link_2"/>
        <child link="Link_3"/>
        <origin xyz="0 0 0" rpy="0 0 0" />
    </joint>

    <joint name="Joint_3" type="continuous">
        <parent link="Link_3"/>
        <child link="Link_4"/>
        <origin xyz="0 0 0" rpy="0 0 0" />
    </joint>

    <joint name="Joint_4" type="continuous">
        <parent link="Link_4"/>
        <child link="Link_5"/>
        <origin xyz="0 0 0" rpy="0 0 0" />
    </joint>

    <joint name="Joint_5" type="continuous">
        <parent link="Link_5"/>
        <child link="Link_6"/>
        <origin xyz="0 0 0" rpy="0 0 0" />
    </joint>

    <joint name="Joint_6" type="continuous">
        <parent link="Link_6"/>
        <child link="Link_7"/>
        <origin xyz="0 0 0" rpy="0 0 0" />
    </joint>

</robot>
