<?xml version="1.0" ?>
<robot name="arm2d" xmlns:xacro="http://www.ros.org/wiki/xacro">


<xacro:include filename="$(find arm2d2_description)/urdf/arm1.gazebo"/>
<xacro:include filename="$(find arm2d2_description)/urdf/arm1.trans"/>



<link name="world"/>

<xacro:if value="${is_left}">
  <link name="link_1">
    <inertial>
      <origin rpy="0 0 0" xyz="-0.00789643305978462 0.002474313899377526 0.01425764348212194"/>
      <mass value="0.17435766910618158"/>
      <inertia ixx="9.7e-05" ixy="7e-06" ixz="2.8e-05" iyy="0.000111" iyz="-1.2e-05" izz="0.000119"/>
    </inertial>
    <visual>
      <origin rpy="0 0 0" xyz="0.003226 0.019004 -0.084836"/>
      <geometry>
        <mesh filename="package://arm2d2_description/meshes/link_1.stl" scale="0.001 0.001 0.001"/>
      </geometry>
      <material name="silver"/>
    </visual>
    <collision>
      <origin rpy="0 0 0" xyz="0.003226 0.019004 -0.084836"/>
      <geometry>
        <mesh filename="package://arm2d2_description/meshes/link_1.stl" scale="0.001 0.001 0.001"/>
      </geometry>
    </collision>
  </link>

  <joint name="joint_1" type="revolute">
    <origin rpy="0 0 0" xyz="-0.003226 -0.019004 0.084836"/>
    <parent link="world"/>
    <child link="link_1"/>
    <axis xyz="-0.0 -0.0 1.0"/>
    <limit effort="100" lower="-3.1415" upper="3.1415" velocity="100"/>
  </joint>
</xacro:if>

<xacro:unless value="${is_left}">
  <link name="link_1">
    <inertial>
      <origin rpy="0 0 0" xyz="0.007896441922670472 0.002474313899377481 0.014257643482122176"/>
      <mass value="0.17435766910618158"/>
      <inertia ixx="9.7e-05" ixy="-7e-06" ixz="-2.8e-05" iyy="0.000111" iyz="-1.2e-05" izz="0.000119"/>
    </inertial>
    <visual>
      <origin rpy="0 0 0" xyz="-0.140459 0.019004 -0.084836"/>
      <geometry>
        <mesh filename="package://arm2d2_description/meshes/right_link_1.stl" scale="0.001 0.001 0.001"/>
      </geometry>
      <material name="silver"/>
    </visual>
    <collision>
      <origin rpy="0 0 0" xyz="-0.140459 0.019004 -0.084836"/>
      <geometry>
        <mesh filename="package://arm2d2_description/meshes/right_link_1.stl" scale="0.001 0.001 0.001"/>
      </geometry>
    </collision>
  </link>

  <joint name="joint_1" type="revolute">
    <origin rpy="0 0 0" xyz="0.140459 -0.019004 0.084836"/>
    <parent link="world"/>
    <child link="link_1"/>
    <axis xyz="-0.0 -0.0 1.0"/>
    <limit effort="100" lower="-3.1415" upper="3.1415" velocity="100"/>
  </joint>

</xacro:unless>

<link name="link_2">
  <inertial>
    <origin rpy="0 0 0" xyz="0.018987093043452495 -8.654849839149874e-06 0.04227959421337937"/>
    <mass value="0.33055155165296496"/>
    <inertia ixx="0.000692" ixy="0.0" ixz="0.000175" iyy="0.000805" iyz="-0.0" izz="0.000196"/>
  </inertial>
  <visual>
    <origin rpy="0 0 0" xyz="0.023226 0.006935 -0.127996"/>
    <geometry>
      <mesh filename="package://arm2d2_description/meshes/link_2.stl" scale="0.001 0.001 0.001"/>
    </geometry>
    <material name="silver"/>
  </visual>
  <collision>
    <origin rpy="0 0 0" xyz="0.023226 0.006935 -0.127996"/>
    <geometry>
      <mesh filename="package://arm2d2_description/meshes/link_2.stl" scale="0.001 0.001 0.001"/>
    </geometry>
  </collision>
</link>

  <joint name="joint_2" type="revolute">
    <xacro:if value="${is_left}">
      <origin rpy="0 0 0" xyz="-0.02 0.012069 0.04316"/>
    </xacro:if>
    <xacro:unless value="${is_left}">
      <origin rpy="0 0 3.14159" xyz="0.02 0.012069 0.04316"/>
    </xacro:unless>
    <parent link="link_1"/>
    <child link="link_2"/>
    <axis xyz="1.0 -0.0 0.0"/>
    <limit effort="100" lower="-1.658063" upper="1.658063" velocity="100"/>
  </joint>


<link name="link_3">
  <inertial>
    <origin rpy="0 0 0" xyz="0.01486624818688466 5.1068847866287195e-05 0.017280828477582222"/>
    <mass value="0.12173297000702284"/>
    <inertia ixx="4.7e-05" ixy="-0.0" ixz="-6e-06" iyy="5e-05" iyz="0.0" izz="2.9e-05"/>
  </inertial>
  <visual>
    <origin rpy="0 0 0" xyz="0.013226 0.006935 -0.247996"/>
    <geometry>
      <mesh filename="package://arm2d2_description/meshes/link_3.stl" scale="0.001 0.001 0.001"/>
    </geometry>
    <material name="silver"/>
  </visual>
  <collision>
    <origin rpy="0 0 0" xyz="0.013226 0.006935 -0.247996"/>
    <geometry>
      <mesh filename="package://arm2d2_description/meshes/link_3.stl" scale="0.001 0.001 0.001"/>
    </geometry>
  </collision>
</link>

<joint name="joint_3" type="revolute">
  <origin rpy="0 0 0" xyz="0.01 0.0 0.12"/>
  <parent link="link_2"/>
  <child link="link_3"/>
  <axis xyz="1.0 -0.0 0.0"/>
  <limit effort="100" lower="-2.268928" upper="2.268928" velocity="100"/>
</joint>

<link name="link_4">
  <inertial>
    <origin rpy="0 0 0" xyz="-0.011101445382475407 3.224282872898998e-05 0.04184113022854269"/>
    <mass value="0.195562429412683"/>
    <inertia ixx="0.00022" ixy="-0.0" ixz="3.5e-05" iyy="0.000227" iyz="0.0" izz="5.5e-05"/>
  </inertial>
  <visual>
    <origin rpy="0 0 0" xyz="-0.006774 0.006935 -0.287996"/>
    <geometry>
      <mesh filename="package://arm2d2_description/meshes/link_4.stl" scale="0.001 0.001 0.001"/>
    </geometry>
    <material name="silver"/>
  </visual>
  <collision>
    <origin rpy="0 0 0" xyz="-0.006774 0.006935 -0.287996"/>
    <geometry>
      <mesh filename="package://arm2d2_description/meshes/link_4.stl" scale="0.001 0.001 0.001"/>
    </geometry>
  </collision>
</link>


<joint name="joint_4" type="revolute">
  <origin rpy="0 0 0" xyz="0.02 0.0 0.04"/>
  <parent link="link_3"/>
  <child link="link_4"/>
  <axis xyz="0.0 7e-06 1.0"/>
  <limit effort="100" lower="-3.1415" upper="3.1415" velocity="100"/>
</joint>


<link name="link_5">
  <inertial>
    <origin rpy="0 0 0" xyz="0.019497247706371294 -2.0405114986837142e-07 0.004294146286032974"/>
    <mass value="0.05413625246465982"/>
    <inertia ixx="1.5e-05" ixy="0.0" ixz="-0.0" iyy="1.8e-05" iyz="-0.0" izz="1.2e-05"/>
  </inertial>
  <visual>
    <origin rpy="0 0 0" xyz="0.003226 0.006934 -0.377996"/>
    <geometry>
      <mesh filename="package://arm2d2_description/meshes/link_5.stl" scale="0.001 0.001 0.001"/>
    </geometry>
    <material name="silver"/>
  </visual>
  <collision>
    <origin rpy="0 0 0" xyz="0.003226 0.006934 -0.377996"/>
    <geometry>
      <mesh filename="package://arm2d2_description/meshes/link_5.stl" scale="0.001 0.001 0.001"/>
    </geometry>
  </collision>
</link>


<joint name="joint_5" type="revolute">
  <origin rpy="0 0 0" xyz="-0.01 1e-06 0.09"/>
  <parent link="link_4"/>
  <child link="link_5"/>
  <axis xyz="1.0 -0.0 0.0"/>
  <limit effort="100" lower="-2.268928" upper="2.268928" velocity="100"/>
</joint>




</robot>

