<?xml version="1.0" encoding="utf-8" ?>

<robot name="arm2d2" xmlns:xacro="http://www.ros.org/wifi/xacro">

  <xacro:arg name="include_arm_base" default="true"/>
  <xacro:arg name="ns" default="left"/>
  <xacro:arg name="include_gripper" default="false"/>
  <xacro:arg name="top_plate" default="false"/>


  <!-- Convert arg to property -->
  <xacro:property name="ns" value="$(arg ns)"/>

  <material name="silver">
    <color rgba="0.700 0.700 0.700 1.000" />
  </material>

  <xacro:if value="$(arg include_arm_base)">
    <xacro:include filename="$(find arm2d2_description)/urdf/base.urdf.xacro"/>
  </xacro:if>

  <xacro:unless value="$(arg include_arm_base)">
    <link name="world"/>

    <link name="base_link"/>

    <joint name="world_joint" type="fixed">
      <parent link="world"/>
      <child link="base_link"/>
      <!-- rpy="1.57 0 0"-->
      <origin xyz="0 0 0.0775" rpy="0 0 0"/>
    </joint>
  </xacro:unless>

  <link name="base_connector">
      <inertial>
      <origin rpy="0 0 0" xyz="0.06861790086338357 -0.0835697992386399 0.07107579694115096"/>
      <mass value="4.519107238213137"/>
      <inertia ixx="0.059779" ixy="-0.0" ixz="0.0" iyy="0.062251" iyz="0.000956" izz="0.076317"/>
    </inertial>
    <visual>
      <origin rpy="0 0 0" xyz="0 0 0"/>
      <geometry>
        <box size="0.001 0.001 0.001"/>
      </geometry>
      <material name="silver"/>
    </visual>
    <collision>
      <origin rpy="0 0 0" xyz="0 0 0"/>
      <geometry>
        <box size="0.001 0.001 0.001"/>
      </geometry>
    </collision>
  </link>

  <joint name="base_connector_joint" type="fixed">
    <parent link="base_link"/>
    <child link="base_connector"/>
    <origin xyz="0 0 -0.005" rpy="1.57 0 0"/>
  </joint>


  <link name="link_1">
    <inertial>
      <origin xyz="-0.023234210000508494 0.032933361084236216 0.002920663644532681" rpy="0 0 0"/>
      <mass value="0.22666453646044638"/>
      <inertia ixx="0.000128" iyy="0.000201" izz="0.000231" ixy="3.1e-05" iyz="-5e-06" ixz="1.5e-05"/>
    </inertial>
    <visual>
      <origin xyz="-0.0851 -0.006604 0.0851" rpy="0 0 0"/>
      <geometry>
        <mesh filename="package://arm2d2_description/meshes/link_1_1.stl" scale="0.001 0.001 0.001"/>
      </geometry>
      <material name="silver"/>
    </visual>
    <collision>
      <origin xyz="-0.0851 -0.006604 0.0851" rpy="0 0 0"/>
      <geometry>
        <mesh filename="package://arm2d2_description/meshes/link_1_1.stl" scale="0.001 0.001 0.001"/>
      </geometry>
    </collision>
  </link>

  
  <joint name="joint_1" type="revolute">
    <!-- p value corresponds to starting point for stepper -->
    <xacro:if value="${ns == 'left'}">
      <!-- p=2.82584 -->
      <origin xyz="0.085 0.006604 -0.085" rpy="0 -0.35  0"/>
    </xacro:if>
    <xacro:unless value="${ns == 'left'}">
      <origin xyz="-0.085 0.006604 -0.085" rpy="0 3.3 0"/>
    </xacro:unless>
    <parent link="base_connector"/>
    <child link="link_1"/>
    <axis xyz="0.0 -1.0 0.0"/>
    <limit effort="100" lower="-3.1415" upper="3.1415" velocity="100"/>
  </joint>



  <link name="link_2">
    <inertial>
      <origin xyz="-0.004298579881610032 0.07240002211825339 0.016744309655985348" rpy="0 0 0"/>
      <mass value="0.2595123095947453"/>
      <inertia ixx="0.000561" iyy="0.000112" izz="0.000572" ixy="-6.1e-05" iyz="-9.9e-05" ixz="-9e-06"/>
    </inertial>
    <visual>
      <origin xyz="-0.090305 -0.046604 0.085785" rpy="0 0 0"/>
      <geometry>
        <mesh filename="package://arm2d2_description/meshes/link_2_1.stl" scale="0.001 0.001 0.001"/>
      </geometry>
      <material name="silver"/>
    </visual>
    <collision>
      <origin xyz="-0.090305 -0.046604 0.085785" rpy="0 0 0"/>
      <geometry>
        <mesh filename="package://arm2d2_description/meshes/link_2_1.stl" scale="0.001 0.001 0.001"/>
      </geometry>
    </collision>
  </link>

  <joint name="joint_2" type="revolute">
    <xacro:if value="${ns == 'left'}">
      <origin xyz="-0.005205 0.04 -0.000685" rpy="-0.436332 3.14 -0.03927"/>
      <limit lower="-1.919862" upper="1.396263" effort="100" velocity="100"/>
    </xacro:if>
    <xacro:unless value="${ns == 'left'}">
      <origin xyz="-0.005205 0.04 -0.000685" rpy="0 3.14 0"/>
      <limit upper="1.919862" lower="-1.396263" effort="100" velocity="100"/>
    </xacro:unless>
    <parent link="link_1" />
    <child link="link_2" />
    <axis xyz="-0.991445 -0.0 0.130526"/>
    
  </joint>

  <link name="link_3">
    <inertial>
      <origin xyz="-0.01624182942995088 -0.0066433309450394384 0.019077247172201647" rpy="0 0 0"/>
      <mass value="0.1304515658530355"/>
      <inertia ixx="5.4e-05" iyy="6.3e-05" izz="4.4e-05" ixy="-2e-06" iyz="8e-06" ixz="7e-06"/>
    </inertial>
    <visual>
      <origin xyz="-0.084346 -0.183285 0.054438" rpy="0 0 0"/>
      <geometry>
        <mesh filename="package://arm2d2_description/meshes/link_3_1.stl" scale="0.001 0.001 0.001"/>
      </geometry>
      <material name="silver"/>
    </visual>
    <collision>
      <origin xyz="-0.084346 -0.183285 0.054438" rpy="0 0 0"/>
      <geometry>
        <mesh filename="package://arm2d2_description/meshes/link_3_1.stl" scale="0.001 0.001 0.001"/>
      </geometry>
    </collision>
  </link>

  <joint name="joint_3" type="revolute">
    <xacro:if value="${ns == 'left'}">
     <origin xyz="-0.005959 0.136681 0.031347" rpy="-3.42078 0.23562 -0.03"/>
     <limit lower="-4.101524" upper="0.698132" effort="100" velocity="100"/>
    </xacro:if>
    <xacro:unless value="${ns == 'left'}">
      <origin xyz="-0.005959 0.136681 0.031347" rpy="0 0 0"/>
      <limit upper="4.101524" lower="-0.698132" effort="100" velocity="100"/>
    </xacro:unless>
    <parent link="link_2" />
    <child link="link_3" />
    <axis xyz="-0.991445 -0.0 0.130526"/>
  </joint>

  <link name="link_4">
    <inertial>
      <origin xyz="0.02326557503032635 -0.017807087000725114 0.04222851748201549" rpy="0 0 0"/>
      <mass value="0.21070496092935861"/>
      <inertia ixx="0.00028" iyy="0.000293" izz="0.000129" ixy="3.4e-05" iyz="8.1e-05" ixz="-8e-05"/>
    </inertial>
    <visual>
      <origin xyz="-0.059366 -0.168718 0.013574" rpy="0 0 0"/>
      <geometry>
        <mesh filename="package://arm2d2_description/meshes/link_4_1.stl" scale="0.001 0.001 0.001"/>
      </geometry>
      <material name="silver"/>
    </visual>
    <collision>
      <origin xyz="-0.059366 -0.168718 0.013574" rpy="0 0 0"/>
      <geometry>
        <mesh filename="package://arm2d2_description/meshes/link_4_1.stl" scale="0.001 0.001 0.001"/>
      </geometry>
    </collision>
  </link>

  <joint name="joint_4" type="revolute">
    <origin xyz="-0.02498 -0.014567 0.040864" rpy="0 0 0"/>
    <parent link="link_3" />
    <child link="link_4" />
    <axis xyz="0.121444 -0.366501 0.922458"/>
    <limit effort="100" lower="-3.1415" upper="3.1415" velocity="100"/>
  </joint>

  
  <link name="link_5">
    <inertial>
      <origin xyz="-0.02075508203374557 -0.023703571758186867 0.0028416884784955576" rpy="0 0 0"/>
      <mass value="0.15989560658307483"/>
      <inertia ixx="8.3e-05" iyy="5.8e-05" izz="9.9e-05" ixy="-1.8e-05" iyz="3e-06" ixz="2e-06"/>
    </inertial>
    <visual>
      <origin xyz="-0.091433 -0.131975 -0.076012" rpy="0 0 0"/>
      <geometry>
        <mesh filename="package://arm2d2_description/meshes/link_5_1.stl" scale="0.001 0.001 0.001"/>
      </geometry>
      <material name="silver"/>
    </visual>
    <collision>
      <origin xyz="-0.091433 -0.131975 -0.076012" rpy="0 0 0"/>
      <geometry>
        <mesh filename="package://arm2d2_description/meshes/link_5_1.stl" scale="0.001 0.001 0.001"/>
      </geometry>
    </collision>
  </link>

  <joint name="joint_5" type="revolute">
    <xacro:if value="${ns == 'left'}">
     <origin xyz="0.032067 -0.036743 0.089586" rpy="-2.38412 0.23562 0.1"/>
     <limit lower="-3.228859" upper="0.785398" effort="100" velocity="100"/>
    </xacro:if>
    <xacro:unless value="${ns == 'left'}">
      <origin xyz="0.032067 -0.036743 0.089586" rpy="0 0 0"/>
      <limit upper="3.228859" lower="-0.785398" effort="100" velocity="100"/>
    </xacro:unless>
    
    <parent link="link_4" />
    <child link="link_5" />
    <axis xyz="-0.991445 -0.0 0.130526"/>
  </joint>

  <!-- Fake link that allows gripper to "spin" even though the hardware does not have a revolute gripper joint -->
  <xacro:if value="$(arg include_gripper)">
    <link name="gripper_connector">
      <inertial>
        <origin rpy="0 0 0" xyz="2.9287E-10 -1.6472E-09 0.0091432"/>
        <mass value="0.013863"/>
        <inertia ixx="1.3596E-06" ixy="3.0585E-13" ixz="5.7102E-14" iyy="1.7157E-06" iyz="6.3369E-09" izz="2.4332E-06"/>
      </inertial>
    </link>
  </xacro:if>

  <!-- Box that provides gripper collider only for moveit so gazebo does not simulate collisions -->
  <xacro:unless value="$(arg include_gripper)">
    <link name="gripper_connector">
      <inertial>
        <origin rpy="0 0 0" xyz="2.9287E-10 -1.6472E-09 0.0091432"/>
        <mass value="0.013863"/>
        <inertia ixx="1.3596E-06" ixy="3.0585E-13" ixz="5.7102E-14" iyy="1.7157E-06" iyz="6.3369E-09" izz="2.4332E-06"/>
      </inertial>
    </link>

    <link name="gripper_collider">
      <xacro:unless value="$(arg include_gripper)">
        <!-- Removed to test sim handoff
        <collision>
          <origin xyz="0.025 0 0.075" rpy="0 0 0" />
          <geometry>
            <box size="0.05 0.05 0.05"/>
          </geometry>
        </collision>
        -->
      </xacro:unless>
      <!--
      <visual>
        <origin xyz="0.025 0 0.075" rpy="0 0 0" />
        <geometry>
          <box size="0.05 0.05 0.05"/>
        </geometry>
      </visual>-->
    </link>

    <joint name="gripper_collider_joint" type="fixed">
      <origin xyz="0 0 0" rpy="0 0 0"/>
      <parent link="link_5"/>
      <child link="gripper_collider"/>
    </joint>
  </xacro:unless>
  
  <joint name="gripper_joint" type="revolute">
    <origin xyz="-0.03 -0.041 0.0045" rpy="0 0 0"/>
    <parent link="link_5"/>
    <child link="gripper_connector"/>
    <axis xyz="0 0 1"/>
    <limit lower="-3.1415" upper="3.1415" effort="100" velocity="100"/>
  </joint>
  <transmission name="transmission_1">
    <type>transmission_interface/SimpleTransmission</type>
    <joint name="joint_1">
      <hardwareInterface>hardware_interface/PositionJointInterface</hardwareInterface>
    </joint>
    <actuator name="motor_1">
      <hardwareInterface>hardware_interface/PositionJointInterface</hardwareInterface>
      <mechanicalReduction>1</mechanicalReduction>
    </actuator>
  </transmission>

  <transmission name="transmission_2">
    <type>transmission_interface/SimpleTransmission</type>
    <joint name="joint_2">
      <hardwareInterface>hardware_interface/PositionJointInterface</hardwareInterface>
    </joint>
    <actuator name="motor_2">
      <hardwareInterface>hardware_interface/PositionJointInterface</hardwareInterface>
      <mechanicalReduction>1</mechanicalReduction>
    </actuator>
  </transmission>

  <transmission name="transmission_3">
    <type>transmission_interface/SimpleTransmission</type>
    <joint name="joint_3">
      <hardwareInterface>hardware_interface/PositionJointInterface</hardwareInterface>
    </joint>
    <actuator name="motor_3">
      <hardwareInterface>hardware_interface/PositionJointInterface</hardwareInterface>
      <mechanicalReduction>1</mechanicalReduction>
    </actuator>
  </transmission>

  <transmission name="transmission_4">
    <type>transmission_interface/SimpleTransmission</type>
    <joint name="joint_4">
      <hardwareInterface>hardware_interface/PositionJointInterface</hardwareInterface>
    </joint>
    <actuator name="motor_4">
      <hardwareInterface>hardware_interface/PositionJointInterface</hardwareInterface>
      <mechanicalReduction>1</mechanicalReduction>
    </actuator>
  </transmission>

  <transmission name="transmission_5">
    <type>transmission_interface/SimpleTransmission</type>
    <joint name="joint_5">
      <hardwareInterface>hardware_interface/PositionJointInterface</hardwareInterface>
    </joint>
    <actuator name="motor_5">
      <hardwareInterface>hardware_interface/PositionJointInterface</hardwareInterface>
      <mechanicalReduction>1</mechanicalReduction>
    </actuator>
  </transmission>

  <transmission name="transmission_6">
    <type>transmission_interface/SimpleTransmission</type>
    <joint name="gripper_joint">
      <hardwareInterface>hardware_interface/PositionJointInterface</hardwareInterface>
    </joint>
    <actuator name="motor_6">
      <hardwareInterface>hardware_interface/PositionJointInterface</hardwareInterface>
      <mechanicalReduction>1</mechanicalReduction>
    </actuator>
  </transmission>

  <gazebo>
    <plugin name="gazebo_ros_control" filename="libgazebo_ros_control.so">
      <!--<robotNamespace>/</robotNamespace>-->
    </plugin>
  </gazebo>

  <gazebo reference="base_link">
    <material>Gazebo/Silver</material>
    <mu1>0.2</mu1>
    <mu2>0.2</mu2>
    <selfCollide>true</selfCollide>
    <gravity>true</gravity>
  </gazebo>

  <gazebo reference="link_1">
    <material>Gazebo/Silver</material>
    <mu1>0.2</mu1>
    <mu2>0.2</mu2>
    <selfCollide>true</selfCollide>
  </gazebo>

  <gazebo reference="link_2">
    <material>Gazebo/Silver</material>
    <mu1>0.2</mu1>
    <mu2>0.2</mu2>
    <selfCollide>true</selfCollide>
  </gazebo>

  <gazebo reference="link_3">
    <material>Gazebo/Silver</material>
    <mu1>0.2</mu1>
    <mu2>0.2</mu2>
    <selfCollide>true</selfCollide>
  </gazebo>

  <gazebo reference="link_4">
    <material>Gazebo/Silver</material>
    <mu1>0.2</mu1>
    <mu2>0.2</mu2>
    <selfCollide>true</selfCollide>
  </gazebo>

  <gazebo reference="link_5">
    <material>Gazebo/Silver</material>
    <mu1>0.2</mu1>
    <mu2>0.2</mu2>
    <selfCollide>true</selfCollide>
  </gazebo>

  <gazebo reference="gripper_joint">
    <material>Gazebo/Silver</material>
    <mu1>0.2</mu1>
    <mu2>0.2</mu2>
    <selfCollide>true</selfCollide>
  </gazebo>


</robot>
