<?xml version="1.0" ?>
<robot name="arm2d" xmlns:xacro="http://www.ros.org/wiki/xacro">


<link name="palm">
  <inertial>
    <origin rpy="0 0 0" xyz="-0.001212486429148927 2.8895706877599125e-09 0.008048309365708495"/>
    <mass value="0.015238456311074547"/>
    <inertia ixx="3e-06" ixy="-0.0" ixz="-0.0" iyy="3e-06" iyz="0.0" izz="5e-06"/>
  </inertial>
  <visual>
    <origin rpy="0 0 0" xyz="-0.021774 0.006934 -0.402996"/>
    <geometry>
      <mesh filename="package://arm2d2_description/meshes/palm.stl" scale="0.001 0.001 0.001"/>
    </geometry>
    <material name="silver"/>
  </visual>
  <collision>
    <origin rpy="0 0 0" xyz="-0.021774 0.006934 -0.402996"/>
    <geometry>
      <mesh filename="package://arm2d2_description/meshes/palm.stl" scale="0.001 0.001 0.001"/>
    </geometry>
  </collision>
</link>


<link name="actuator_1">
  <inertial>
    <origin rpy="0 0 0" xyz="-0.003835486476855776 -0.004713873695782212 0.02727947292495564"/>
    <mass value="0.005277222771828628"/>
    <inertia ixx="2e-06" ixy="0.0" ixz="0.0" iyy="2e-06" iyz="-0.0" izz="0.0"/>
  </inertial>
  <visual>
    <origin rpy="0 0 0" xyz="-0.044603 0.01307 -0.424996"/>
    <geometry>
      <mesh filename="package://arm2d2_description/meshes/actuator_1.stl" scale="0.001 0.001 0.001"/>
    </geometry>
    <material name="silver"/>
  </visual>
  <collision>
    <origin rpy="0 0 0" xyz="-0.044603 0.01307 -0.424996"/>
    <geometry>
      <mesh filename="package://arm2d2_description/meshes/actuator_1.stl" scale="0.001 0.001 0.001"/>
    </geometry>
  </collision>
</link>


<joint name="actuator_joint_1" type="revolute">
  <origin rpy="0 0 0" xyz="0.022829 -0.006136 0.022"/>
  <parent link="palm"/>
  <child link="actuator_1"/>
  <axis xyz="0.5 0.866025 -6e-06"/>
  <limit effort="100" lower="-0.1" upper="1.570796" velocity="100"/>
</joint>

<link name="actuator_2">
  <inertial>
    <origin rpy="0 0 0" xyz="-0.0021646025973648094 0.00567892122346535 0.027279474187493602"/>
    <mass value="0.005277222771828628"/>
    <inertia ixx="2e-06" ixy="-0.0" ixz="-0.0" iyy="2e-06" iyz="-0.0" izz="0.0"/>
  </inertial>
  <visual>
    <origin rpy="0 0 0" xyz="-0.005046 0.023636 -0.424996"/>
    <geometry>
      <mesh filename="package://arm2d2_description/meshes/actuator_2.stl" scale="0.001 0.001 0.001"/>
    </geometry>
    <material name="silver"/>
  </visual>
  <collision>
    <origin rpy="0 0 0" xyz="-0.005046 0.023636 -0.424996"/>
    <geometry>
      <mesh filename="package://arm2d2_description/meshes/actuator_2.stl" scale="0.001 0.001 0.001"/>
    </geometry>
  </collision>
</link>


<joint name="actuator_joint_2" type="revolute">
  <origin rpy="0 0 0" xyz="-0.016728 -0.016702 0.022"/>
  <parent link="palm"/>
  <child link="actuator_2"/>
  <axis xyz="0.5 -0.866025 6e-06"/>
  <limit effort="100" lower="-0.1" upper="1.658063" velocity="100"/>
</joint>

<link name="actuator_3">
  <inertial>
    <origin rpy="0 0 0" xyz="0.006000455462889673 -0.000964137225942182 0.02727923439293578"/>
    <mass value="0.005277222771828628"/>
    <inertia ixx="2e-06" ixy="0.0" ixz="0.0" iyy="2e-06" iyz="0.0" izz="0.0"/>
  </inertial>
  <visual>
    <origin rpy="0 0 0" xyz="-0.015674 -0.015904 -0.424996"/>
    <geometry>
      <mesh filename="package://arm2d2_description/meshes/actuator_3.stl" scale="0.001 0.001 0.001"/>
    </geometry>
    <material name="silver"/>
  </visual>
  <collision>
    <origin rpy="0 0 0" xyz="-0.015674 -0.015904 -0.424996"/>
    <geometry>
      <mesh filename="package://arm2d2_description/meshes/actuator_3.stl" scale="0.001 0.001 0.001"/>
    </geometry>
  </collision>
</link>


<joint name="actuator_joint_3" type="revolute">
  <origin rpy="0 0 0" xyz="-0.0061 0.022838 0.022"/>
  <parent link="palm"/>
  <child link="actuator_3"/>
  <axis xyz="-1.0 -0.0 -0.0"/>
  <limit effort="100" lower="-0.1" upper="1.658063" velocity="100"/>
</joint>

<link name="gripper_driver">
  <inertial>
    <origin rpy="0 0 0" xyz="4.5546288952522107e-07 2.537799107145411e-09 0.0030000469930032136"/>
    <mass value="0.017198611293271295"/>
    <inertia ixx="1e-06" ixy="0.0" ixz="0.0" iyy="1e-06" iyz="0.0" izz="2e-06"/>
  </inertial>
  <visual>
    <origin rpy="0 0 0" xyz="-0.021774 0.006934 -0.407996"/>
    <geometry>
      <mesh filename="package://arm2d2_description/meshes/gripper_driver.stl" scale="0.001 0.001 0.001"/>
    </geometry>
    <material name="silver"/>
  </visual>
  <collision>
    <origin rpy="0 0 0" xyz="-0.021774 0.006934 -0.407996"/>
    <geometry>
      <mesh filename="package://arm2d2_description/meshes/gripper_driver.stl" scale="0.001 0.001 0.001"/>
    </geometry>
  </collision>
</link>



<joint name="gripper_driver_joint" type="prismatic">
  <origin rpy="0 0 0" xyz="0.0 0.0 0.005"/>
  <parent link="palm"/>
  <child link="gripper_driver"/>
  <axis xyz="0.0 -7e-06 -1.0"/>
  <limit effort="100" lower="-0.025" upper="-0.0140" velocity="100"/>
</joint>

</robot>
