<?xml version="1.0" encoding="utf-8"?>

<robot xmlns:xacro="http://www.ros.org/wiki/xacro" name="tundra_gripper">

  <xacro:arg name="ns" default=""/>

  <link name="world"/>
  <link name="gripper_link"/>

  <joint name="world_joint" type="fixed">
    <origin xyz="0 0 0" rpy="0 0 0"/>
    <parent link="world"/>
    <child link="gripper_link"/>
  </joint>

  <link name="palm">
    <inertial>
      <origin rpy="0 0 0" xyz="0.02043962300807103 -1.5866844334157942e-07 0.010610125536728798"/>
      <mass value="0.06937470143360883"/>
      <inertia ixx="2.7e-05" ixy="-0.0" ixz="-2e-06" iyy="3.1e-05" iyz="-0.0" izz="1.7e-05"/>
    </inertial>
    <visual>
      <origin rpy="0 0 0" xyz="0.003226 0.006934 -0.377996"/>
      <geometry>
        <mesh filename="package://ar_mini_description/meshes/palm_1.stl" scale="0.001 0.001 0.001"/>
      </geometry>
      <material name="silver"/>
    </visual>
    <collision>
      <origin rpy="0 0 0" xyz="0.003226 0.006934 -0.377996"/>
      <geometry>
        <mesh filename="package://ar_mini_description/meshes/palm_1.stl" scale="0.001 0.001 0.001"/>
      </geometry>
    </collision>
  </link>

  <joint name="palm_joint" type="fixed">
    <origin  xyz="-0.01 1e-06 0.09" rpy="0 0 0"/>
    <parent link="gripper_link"/>
    <child link="palm"/>
  </joint>


  <link name="actuator_1">
    <inertial>
      <origin rpy="0 0 0" xyz="0.0021645135231446733 0.0056789212234661345 0.027279474187493324"/>
      <mass value="0.005277222771828628"/>
      <inertia ixx="2e-06" ixy="0.0" ixz="0.0" iyy="2e-06" iyz="-0.0" izz="0.0"/>
    </inertial>
    <visual>
      <origin rpy="0 0 0" xyz="-0.038503 0.023636 -0.424996"/>
      <geometry>
        <mesh filename="package://ar_mini_description/meshes/finger_1.stl" scale="0.001 0.001 0.001"/>
      </geometry>
      <material name="silver"/>
    </visual>
    <collision>
      <origin rpy="0 0 0" xyz="-0.038503 0.023636 -0.424996"/>
      <geometry>
        <mesh filename="package://ar_mini_description/meshes/finger_1.stl" scale="0.001 0.001 0.001"/>
      </geometry>
    </collision>
  </link>

  <joint name="actuator_joint_1" type="revolute">
    <origin rpy="0 0 0" xyz="0.041729 -0.016702 0.047"/>
    <parent link="palm"/>
    <child link="actuator_1"/>
    <axis xyz="-0.5 -0.866025 6e-06"/>
    <limit effort="100" lower="-0.698132" upper="0.0" velocity="100"/>
  </joint>

  <link name="actuator_2">
    <inertial>
      <origin rpy="0 0 0" xyz="-0.0021646025973648094 0.00567892122346535 0.027279474187493602"/>
      <mass value="0.005277222771828628"/>
      <inertia ixx="2e-06" ixy="-0.0" ixz="-0.0" iyy="2e-06" iyz="-0.0" izz="0.0"/>
    </inertial>
    <visual>
      <origin rpy="0 0 0" xyz="-0.005046 0.023636 -0.424996"/>
      <geometry>
        <mesh filename="package://ar_mini_description/meshes/finger_2.stl" scale="0.001 0.001 0.001"/>
      </geometry>
      <material name="silver"/>
    </visual>
    <collision>
      <origin rpy="0 0 0" xyz="-0.005046 0.023636 -0.424996"/>
      <geometry>
        <mesh filename="package://ar_mini_description/meshes/finger_2.stl" scale="0.001 0.001 0.001"/>
      </geometry>
    </collision>
  </link>


  <joint name="actuator_joint_2" type="revolute">
    <origin rpy="0 0 0" xyz="0.008272 -0.016702 0.047"/>
    <parent link="palm"/>
    <child link="actuator_2"/>
    <axis xyz="0.5 -0.866025 6e-06"/>
    <limit effort="100" lower="0.0" upper="0.698132" velocity="100"/>
  </joint>

  <link name="actuator_3">
    <inertial>
      <origin rpy="0 0 0" xyz="0.006000455462889673 -0.000964137225942182 0.02727923439293578"/>
      <mass value="0.005277222771828628"/>
      <inertia ixx="2e-06" ixy="0.0" ixz="0.0" iyy="2e-06" iyz="0.0" izz="0.0"/>
    </inertial>
    <visual>
      <origin rpy="0 0 0" xyz="-0.015674 -0.015904 -0.424996"/>
      <geometry>
        <mesh filename="package://ar_mini_description/meshes/finger_3.stl" scale="0.001 0.001 0.001"/>
      </geometry>
      <material name="silver"/>
    </visual>
    <collision>
      <origin rpy="0 0 0" xyz="-0.015674 -0.015904 -0.424996"/>
      <geometry>
        <mesh filename="package://ar_mini_description/meshes/finger_3.stl" scale="0.001 0.001 0.001"/>
      </geometry>
    </collision>
  </link>

  <joint name="actuator_joint_3" type="revolute">
    <origin rpy="0 0 0" xyz="0.0189 0.022838 0.047"/>
    <parent link="palm"/>
    <child link="actuator_3"/>
    <axis xyz="-1.0 0.0 -0.0"/>
    <limit effort="100" lower="0.0" upper="0.698132" velocity="100"/>
  </joint>

    <transmission name="transmission_1">
        <type>transmission_interface/SimpleTransmission</type>
        <joint name="actuator_joint_1">
            <hardwareInterface>hardware_interface/PositionJointInterface</hardwareInterface>
        </joint>
        <actuator name="motor_1">
            <hardwareInterface>hardware_interface/PositionJointInterface</hardwareInterface>
            <mechanicalReduction>1</mechanicalReduction>
        </actuator>
    </transmission>  

    <transmission name="transmission_2">
        <type>transmission_interface/SimpleTransmission</type>
        <joint name="actuator_joint_2">
            <hardwareInterface>hardware_interface/PositionJointInterface</hardwareInterface>
        </joint>
        <actuator name="motor_2">
            <hardwareInterface>hardware_interface/PositionJointInterface</hardwareInterface>
            <mechanicalReduction>1</mechanicalReduction>
        </actuator>
    </transmission>

    <transmission name="transmission_3">
        <type>transmission_interface/SimpleTransmission</type>
        <joint name="actuator_joint_3">
            <hardwareInterface>hardware_interface/PositionJointInterface</hardwareInterface>
        </joint>
        <actuator name="motor_3">
            <hardwareInterface>hardware_interface/PositionJointInterface</hardwareInterface>
            <mechanicalReduction>1</mechanicalReduction>
        </actuator>
    </transmission>


    <gazebo>
      <plugin name="gazebo_ros_control" filename="libgazebo_ros_control.so">
        <robotNamespace>$(arg ns)/gripper</robotNamespace>
      </plugin>
    </gazebo>

    <gazebo reference="actuator_1">
        <selfCollide>true</selfCollide>
    </gazebo>
    <gazebo reference="actuator_2">
        <selfCollide>true</selfCollide>
    </gazebo>
      <gazebo reference="actuator_3">
        <selfCollide>true</selfCollide>
    </gazebo>
</robot>